[2023-09-02T15:03:38.448+0000] {taskinstance.py:1159} INFO - Dependencies all met for dep_context=non-requeueable deps ti=<TaskInstance: crawling_news.entertainment scheduled__2023-09-01T15:00:00+00:00 [queued]>
[2023-09-02T15:03:38.463+0000] {taskinstance.py:1159} INFO - Dependencies all met for dep_context=requeueable deps ti=<TaskInstance: crawling_news.entertainment scheduled__2023-09-01T15:00:00+00:00 [queued]>
[2023-09-02T15:03:38.465+0000] {taskinstance.py:1361} INFO - Starting attempt 1 of 1
[2023-09-02T15:03:38.484+0000] {taskinstance.py:1382} INFO - Executing <Task(BashOperator): entertainment> on 2023-09-01 15:00:00+00:00
[2023-09-02T15:03:38.491+0000] {standard_task_runner.py:57} INFO - Started process 26097 to run task
[2023-09-02T15:03:38.498+0000] {standard_task_runner.py:84} INFO - Running: ['***', 'tasks', 'run', 'crawling_news', 'entertainment', 'scheduled__2023-09-01T15:00:00+00:00', '--job-id', '119', '--raw', '--subdir', 'DAGS_FOLDER/crawling_dag.py', '--cfg-path', '/tmp/tmp1dpozvvt']
[2023-09-02T15:03:38.501+0000] {standard_task_runner.py:85} INFO - Job 119: Subtask entertainment
[2023-09-02T15:03:38.574+0000] {task_command.py:415} INFO - Running <TaskInstance: crawling_news.entertainment scheduled__2023-09-01T15:00:00+00:00 [running]> on host 8ef33824b8b6
[2023-09-02T15:03:38.697+0000] {taskinstance.py:1660} INFO - Exporting env vars: AIRFLOW_CTX_DAG_OWNER='***' AIRFLOW_CTX_DAG_ID='crawling_news' AIRFLOW_CTX_TASK_ID='entertainment' AIRFLOW_CTX_EXECUTION_DATE='2023-09-01T15:00:00+00:00' AIRFLOW_CTX_TRY_NUMBER='1' AIRFLOW_CTX_DAG_RUN_ID='scheduled__2023-09-01T15:00:00+00:00'
[2023-09-02T15:03:38.700+0000] {subprocess.py:63} INFO - Tmp dir root location: /tmp
[2023-09-02T15:03:38.703+0000] {subprocess.py:75} INFO - Running command: ['/bin/bash', '-c', 'cd /opt/***/ && python src/crawling.py -s hankook -c entertainment -d 20230901']
[2023-09-02T15:03:38.722+0000] {subprocess.py:86} INFO - Output:
[2023-09-02T15:03:55.006+0000] {subprocess.py:93} INFO - Culture ['HF99', 'HF02', 'HF03', 'HF04', 'HF05', 'HF06'] 20230901
[2023-09-02T15:03:55.037+0000] {subprocess.py:93} INFO - Traceback (most recent call last):
[2023-09-02T15:03:55.041+0000] {subprocess.py:93} INFO -   File "/home/***/.local/lib/python3.8/site-packages/aiohttp/connector.py", line 1155, in _create_direct_connection
[2023-09-02T15:03:55.048+0000] {subprocess.py:93} INFO -     hosts = await asyncio.shield(host_resolved)
[2023-09-02T15:03:55.050+0000] {subprocess.py:93} INFO -   File "/home/***/.local/lib/python3.8/site-packages/aiohttp/connector.py", line 874, in _resolve_host
[2023-09-02T15:03:55.054+0000] {subprocess.py:93} INFO -     addrs = await self._resolver.resolve(host, port, family=self._family)
[2023-09-02T15:03:55.058+0000] {subprocess.py:93} INFO -   File "/home/***/.local/lib/python3.8/site-packages/aiohttp/resolver.py", line 33, in resolve
[2023-09-02T15:03:55.063+0000] {subprocess.py:93} INFO -     infos = await self._loop.getaddrinfo(
[2023-09-02T15:03:55.065+0000] {subprocess.py:93} INFO -   File "/usr/local/lib/python3.8/asyncio/base_events.py", line 825, in getaddrinfo
[2023-09-02T15:03:55.067+0000] {subprocess.py:93} INFO -     return await self.run_in_executor(
[2023-09-02T15:03:55.072+0000] {subprocess.py:93} INFO -   File "/usr/local/lib/python3.8/concurrent/futures/thread.py", line 57, in run
[2023-09-02T15:03:55.074+0000] {subprocess.py:93} INFO -     result = self.fn(*self.args, **self.kwargs)
[2023-09-02T15:03:55.078+0000] {subprocess.py:93} INFO -   File "/usr/local/lib/python3.8/socket.py", line 918, in getaddrinfo
[2023-09-02T15:03:55.080+0000] {subprocess.py:93} INFO -     for res in _socket.getaddrinfo(host, port, family, type, proto, flags):
[2023-09-02T15:03:55.081+0000] {subprocess.py:93} INFO - socket.gaierror: [Errno -3] Temporary failure in name resolution
[2023-09-02T15:03:55.082+0000] {subprocess.py:93} INFO - 
[2023-09-02T15:03:55.083+0000] {subprocess.py:93} INFO - The above exception was the direct cause of the following exception:
[2023-09-02T15:03:55.084+0000] {subprocess.py:93} INFO - 
[2023-09-02T15:03:55.085+0000] {subprocess.py:93} INFO - Traceback (most recent call last):
[2023-09-02T15:03:55.087+0000] {subprocess.py:93} INFO -   File "src/crawling.py", line 135, in <module>
[2023-09-02T15:03:55.091+0000] {subprocess.py:93} INFO -     main()
[2023-09-02T15:03:55.098+0000] {subprocess.py:93} INFO -   File "src/crawling.py", line 126, in main
[2023-09-02T15:03:55.099+0000] {subprocess.py:93} INFO -     loop.run_until_complete(run(site, main_category, sub_category, date))
[2023-09-02T15:03:55.102+0000] {subprocess.py:93} INFO -   File "/usr/local/lib/python3.8/asyncio/base_events.py", line 616, in run_until_complete
[2023-09-02T15:03:55.106+0000] {subprocess.py:93} INFO -     return future.result()
[2023-09-02T15:03:55.109+0000] {subprocess.py:93} INFO -   File "src/crawling.py", line 92, in run
[2023-09-02T15:03:55.111+0000] {subprocess.py:93} INFO -     await asyncio.gather(*futures)
[2023-09-02T15:03:55.113+0000] {subprocess.py:93} INFO -   File "src/crawling.py", line 64, in get_news
[2023-09-02T15:03:55.115+0000] {subprocess.py:93} INFO -     news_list_html = await get_html(search_url)
[2023-09-02T15:03:55.119+0000] {subprocess.py:93} INFO -   File "src/crawling.py", line 32, in get_html
[2023-09-02T15:03:55.125+0000] {subprocess.py:93} INFO -     async with session.get(url, headers={'User-Agent':'Mozilla/5.0'}) as resp:
[2023-09-02T15:03:55.128+0000] {subprocess.py:93} INFO -   File "/home/***/.local/lib/python3.8/site-packages/aiohttp/client.py", line 1141, in __aenter__
[2023-09-02T15:03:55.130+0000] {subprocess.py:93} INFO -     self._resp = await self._coro
[2023-09-02T15:03:55.134+0000] {subprocess.py:93} INFO -   File "/home/***/.local/lib/python3.8/site-packages/aiohttp/client.py", line 536, in _request
[2023-09-02T15:03:55.140+0000] {subprocess.py:93} INFO -     conn = await self._connector.connect(
[2023-09-02T15:03:55.143+0000] {subprocess.py:93} INFO -   File "/home/***/.local/lib/python3.8/site-packages/aiohttp/connector.py", line 540, in connect
[2023-09-02T15:03:55.145+0000] {subprocess.py:93} INFO -     proto = await self._create_connection(req, traces, timeout)
[2023-09-02T15:03:55.148+0000] {subprocess.py:93} INFO -   File "/home/***/.local/lib/python3.8/site-packages/aiohttp/connector.py", line 901, in _create_connection
[2023-09-02T15:03:55.150+0000] {subprocess.py:93} INFO -     _, proto = await self._create_direct_connection(req, traces, timeout)
[2023-09-02T15:03:55.151+0000] {subprocess.py:93} INFO -   File "/home/***/.local/lib/python3.8/site-packages/aiohttp/connector.py", line 1169, in _create_direct_connection
[2023-09-02T15:03:55.154+0000] {subprocess.py:93} INFO -     raise ClientConnectorError(req.connection_key, exc) from exc
[2023-09-02T15:03:55.156+0000] {subprocess.py:93} INFO - aiohttp.client_exceptions.ClientConnectorError: Cannot connect to host hankookilbo.com:443 ssl:default [Temporary failure in name resolution]
[2023-09-02T15:03:55.506+0000] {subprocess.py:97} INFO - Command exited with return code 1
[2023-09-02T15:03:55.557+0000] {taskinstance.py:1943} ERROR - Task failed with exception
Traceback (most recent call last):
  File "/home/airflow/.local/lib/python3.8/site-packages/airflow/operators/bash.py", line 210, in execute
    raise AirflowException(
airflow.exceptions.AirflowException: Bash command failed. The command returned a non-zero exit code 1.
[2023-09-02T15:03:55.582+0000] {taskinstance.py:1400} INFO - Marking task as FAILED. dag_id=crawling_news, task_id=entertainment, execution_date=20230901T150000, start_date=20230902T150338, end_date=20230902T150355
[2023-09-02T15:03:55.647+0000] {standard_task_runner.py:104} ERROR - Failed to execute job 119 for task entertainment (Bash command failed. The command returned a non-zero exit code 1.; 26097)
[2023-09-02T15:03:55.737+0000] {local_task_job_runner.py:228} INFO - Task exited with return code 1
[2023-09-02T15:03:55.800+0000] {taskinstance.py:2784} INFO - 0 downstream tasks scheduled from follow-on schedule check
