[2023-09-01T06:37:39.774+0000] {taskinstance.py:1159} INFO - Dependencies all met for dep_context=non-requeueable deps ti=<TaskInstance: bash_test.culture manual__2023-09-01T06:37:01.593881+00:00 [queued]>
[2023-09-01T06:37:39.934+0000] {taskinstance.py:1159} INFO - Dependencies all met for dep_context=requeueable deps ti=<TaskInstance: bash_test.culture manual__2023-09-01T06:37:01.593881+00:00 [queued]>
[2023-09-01T06:37:39.936+0000] {taskinstance.py:1361} INFO - Starting attempt 1 of 1
[2023-09-01T06:37:40.242+0000] {taskinstance.py:1382} INFO - Executing <Task(BashOperator): culture> on 2023-09-01 06:37:01.593881+00:00
[2023-09-01T06:37:40.288+0000] {standard_task_runner.py:57} INFO - Started process 17172 to run task
[2023-09-01T06:37:40.345+0000] {standard_task_runner.py:84} INFO - Running: ['***', 'tasks', 'run', 'bash_test', 'culture', 'manual__2023-09-01T06:37:01.593881+00:00', '--job-id', '53', '--raw', '--subdir', 'DAGS_FOLDER/test_dags2.py', '--cfg-path', '/tmp/tmpn3uct13x']
[2023-09-01T06:37:40.395+0000] {standard_task_runner.py:85} INFO - Job 53: Subtask culture
[2023-09-01T06:37:40.594+0000] {task_command.py:415} INFO - Running <TaskInstance: bash_test.culture manual__2023-09-01T06:37:01.593881+00:00 [running]> on host 8ef33824b8b6
[2023-09-01T06:37:40.881+0000] {taskinstance.py:1660} INFO - Exporting env vars: AIRFLOW_CTX_DAG_OWNER='***' AIRFLOW_CTX_DAG_ID='bash_test' AIRFLOW_CTX_TASK_ID='culture' AIRFLOW_CTX_EXECUTION_DATE='2023-09-01T06:37:01.593881+00:00' AIRFLOW_CTX_TRY_NUMBER='1' AIRFLOW_CTX_DAG_RUN_ID='manual__2023-09-01T06:37:01.593881+00:00'
[2023-09-01T06:37:40.886+0000] {subprocess.py:63} INFO - Tmp dir root location: /tmp
[2023-09-01T06:37:40.893+0000] {subprocess.py:75} INFO - Running command: ['/bin/bash', '-c', 'cd /opt/***/ && python src/crawling.py -s hankook -c culture -d 20230831']
[2023-09-01T06:37:40.947+0000] {subprocess.py:86} INFO - Output:
[2023-09-01T06:38:49.081+0000] {subprocess.py:93} INFO - Culture ['HE01', 'HE02', 'HE99'] 20230831
[2023-09-01T06:38:49.332+0000] {subprocess.py:93} INFO - Traceback (most recent call last):
[2023-09-01T06:38:49.334+0000] {subprocess.py:93} INFO -   File "/home/***/.local/lib/python3.8/site-packages/aiohttp/connector.py", line 1155, in _create_direct_connection
[2023-09-01T06:38:49.341+0000] {subprocess.py:93} INFO -     hosts = await asyncio.shield(host_resolved)
[2023-09-01T06:38:49.348+0000] {subprocess.py:93} INFO -   File "/home/***/.local/lib/python3.8/site-packages/aiohttp/connector.py", line 874, in _resolve_host
[2023-09-01T06:38:49.362+0000] {subprocess.py:93} INFO -     addrs = await self._resolver.resolve(host, port, family=self._family)
[2023-09-01T06:38:49.366+0000] {subprocess.py:93} INFO -   File "/home/***/.local/lib/python3.8/site-packages/aiohttp/resolver.py", line 33, in resolve
[2023-09-01T06:38:49.372+0000] {subprocess.py:93} INFO -     infos = await self._loop.getaddrinfo(
[2023-09-01T06:38:49.432+0000] {subprocess.py:93} INFO -   File "/usr/local/lib/python3.8/asyncio/base_events.py", line 825, in getaddrinfo
[2023-09-01T06:38:49.456+0000] {subprocess.py:93} INFO -     return await self.run_in_executor(
[2023-09-01T06:38:49.460+0000] {subprocess.py:93} INFO -   File "/usr/local/lib/python3.8/concurrent/futures/thread.py", line 57, in run
[2023-09-01T06:38:49.499+0000] {subprocess.py:93} INFO -     result = self.fn(*self.args, **self.kwargs)
[2023-09-01T06:38:49.504+0000] {subprocess.py:93} INFO -   File "/usr/local/lib/python3.8/socket.py", line 918, in getaddrinfo
[2023-09-01T06:38:49.507+0000] {subprocess.py:93} INFO -     for res in _socket.getaddrinfo(host, port, family, type, proto, flags):
[2023-09-01T06:38:49.512+0000] {subprocess.py:93} INFO - socket.gaierror: [Errno -3] Temporary failure in name resolution
[2023-09-01T06:38:49.514+0000] {subprocess.py:93} INFO - 
[2023-09-01T06:38:49.516+0000] {subprocess.py:93} INFO - The above exception was the direct cause of the following exception:
[2023-09-01T06:38:49.518+0000] {subprocess.py:93} INFO - 
[2023-09-01T06:38:49.520+0000] {subprocess.py:93} INFO - Traceback (most recent call last):
[2023-09-01T06:38:49.523+0000] {subprocess.py:93} INFO -   File "src/crawling.py", line 135, in <module>
[2023-09-01T06:38:49.524+0000] {subprocess.py:93} INFO -     main()
[2023-09-01T06:38:49.526+0000] {subprocess.py:93} INFO -   File "src/crawling.py", line 126, in main
[2023-09-01T06:38:49.527+0000] {subprocess.py:93} INFO -     loop.run_until_complete(run(site, main_category, sub_category, date))
[2023-09-01T06:38:49.528+0000] {subprocess.py:93} INFO -   File "/usr/local/lib/python3.8/asyncio/base_events.py", line 616, in run_until_complete
[2023-09-01T06:38:49.530+0000] {subprocess.py:93} INFO -     return future.result()
[2023-09-01T06:38:49.531+0000] {subprocess.py:93} INFO -   File "src/crawling.py", line 92, in run
[2023-09-01T06:38:49.532+0000] {subprocess.py:93} INFO -     await asyncio.gather(*futures)
[2023-09-01T06:38:49.534+0000] {subprocess.py:93} INFO -   File "src/crawling.py", line 64, in get_news
[2023-09-01T06:38:49.535+0000] {subprocess.py:93} INFO -     news_list_html = await get_html(search_url)
[2023-09-01T06:38:49.537+0000] {subprocess.py:93} INFO -   File "src/crawling.py", line 32, in get_html
[2023-09-01T06:38:49.542+0000] {subprocess.py:93} INFO -     async with session.get(url, headers={'User-Agent':'Mozilla/5.0'}) as resp:
[2023-09-01T06:38:49.546+0000] {subprocess.py:93} INFO -   File "/home/***/.local/lib/python3.8/site-packages/aiohttp/client.py", line 1141, in __aenter__
[2023-09-01T06:38:49.550+0000] {subprocess.py:93} INFO -     self._resp = await self._coro
[2023-09-01T06:38:49.556+0000] {subprocess.py:93} INFO -   File "/home/***/.local/lib/python3.8/site-packages/aiohttp/client.py", line 536, in _request
[2023-09-01T06:38:49.562+0000] {subprocess.py:93} INFO -     conn = await self._connector.connect(
[2023-09-01T06:38:49.571+0000] {subprocess.py:93} INFO -   File "/home/***/.local/lib/python3.8/site-packages/aiohttp/connector.py", line 540, in connect
[2023-09-01T06:38:49.578+0000] {subprocess.py:93} INFO -     proto = await self._create_connection(req, traces, timeout)
[2023-09-01T06:38:49.581+0000] {subprocess.py:93} INFO -   File "/home/***/.local/lib/python3.8/site-packages/aiohttp/connector.py", line 901, in _create_connection
[2023-09-01T06:38:49.583+0000] {subprocess.py:93} INFO -     _, proto = await self._create_direct_connection(req, traces, timeout)
[2023-09-01T06:38:49.623+0000] {subprocess.py:93} INFO -   File "/home/***/.local/lib/python3.8/site-packages/aiohttp/connector.py", line 1169, in _create_direct_connection
[2023-09-01T06:38:49.642+0000] {subprocess.py:93} INFO -     raise ClientConnectorError(req.connection_key, exc) from exc
[2023-09-01T06:38:49.653+0000] {subprocess.py:93} INFO - aiohttp.client_exceptions.ClientConnectorError: Cannot connect to host www.hankookilbo.com:443 ssl:default [Temporary failure in name resolution]
[2023-09-01T06:38:50.566+0000] {subprocess.py:97} INFO - Command exited with return code 1
[2023-09-01T06:38:50.737+0000] {taskinstance.py:1943} ERROR - Task failed with exception
Traceback (most recent call last):
  File "/home/airflow/.local/lib/python3.8/site-packages/airflow/operators/bash.py", line 210, in execute
    raise AirflowException(
airflow.exceptions.AirflowException: Bash command failed. The command returned a non-zero exit code 1.
[2023-09-01T06:38:50.812+0000] {taskinstance.py:1400} INFO - Marking task as FAILED. dag_id=bash_test, task_id=culture, execution_date=20230901T063701, start_date=20230901T063739, end_date=20230901T063850
[2023-09-01T06:38:51.030+0000] {standard_task_runner.py:104} ERROR - Failed to execute job 53 for task culture (Bash command failed. The command returned a non-zero exit code 1.; 17172)
[2023-09-01T06:38:51.183+0000] {local_task_job_runner.py:228} INFO - Task exited with return code 1
[2023-09-01T06:38:51.279+0000] {taskinstance.py:2784} INFO - 0 downstream tasks scheduled from follow-on schedule check
