[2023-09-01T06:56:55.383+0000] {taskinstance.py:1159} INFO - Dependencies all met for dep_context=non-requeueable deps ti=<TaskInstance: bash_test.international scheduled__2023-08-31T06:52:00+00:00 [queued]>
[2023-09-01T06:56:55.532+0000] {taskinstance.py:1159} INFO - Dependencies all met for dep_context=requeueable deps ti=<TaskInstance: bash_test.international scheduled__2023-08-31T06:52:00+00:00 [queued]>
[2023-09-01T06:56:55.543+0000] {taskinstance.py:1361} INFO - Starting attempt 2 of 2
[2023-09-01T06:56:55.633+0000] {taskinstance.py:1382} INFO - Executing <Task(BashOperator): international> on 2023-08-31 06:52:00+00:00
[2023-09-01T06:56:55.670+0000] {standard_task_runner.py:57} INFO - Started process 25121 to run task
[2023-09-01T06:56:55.697+0000] {standard_task_runner.py:84} INFO - Running: ['***', 'tasks', 'run', 'bash_test', 'international', 'scheduled__2023-08-31T06:52:00+00:00', '--job-id', '73', '--raw', '--subdir', 'DAGS_FOLDER/test_dags2.py', '--cfg-path', '/tmp/tmp43oqdqli']
[2023-09-01T06:56:55.707+0000] {standard_task_runner.py:85} INFO - Job 73: Subtask international
[2023-09-01T06:56:55.878+0000] {task_command.py:415} INFO - Running <TaskInstance: bash_test.international scheduled__2023-08-31T06:52:00+00:00 [running]> on host 8ef33824b8b6
[2023-09-01T06:56:56.434+0000] {taskinstance.py:1660} INFO - Exporting env vars: AIRFLOW_CTX_DAG_OWNER='***' AIRFLOW_CTX_DAG_ID='bash_test' AIRFLOW_CTX_TASK_ID='international' AIRFLOW_CTX_EXECUTION_DATE='2023-08-31T06:52:00+00:00' AIRFLOW_CTX_TRY_NUMBER='2' AIRFLOW_CTX_DAG_RUN_ID='scheduled__2023-08-31T06:52:00+00:00'
[2023-09-01T06:56:56.460+0000] {subprocess.py:63} INFO - Tmp dir root location: /tmp
[2023-09-01T06:56:56.473+0000] {subprocess.py:75} INFO - Running command: ['/bin/bash', '-c', 'cd /opt/***/ && python src/crawling.py -s hankook -c international -d 20230831']
[2023-09-01T06:56:56.609+0000] {subprocess.py:86} INFO - Output:
[2023-09-01T06:58:13.661+0000] {subprocess.py:93} INFO - World ['HD01', 'HD02', 'HD03', 'HD04', 'HD05', 'HD99'] 20230831
[2023-09-01T06:58:13.759+0000] {subprocess.py:93} INFO - Traceback (most recent call last):
[2023-09-01T06:58:13.767+0000] {subprocess.py:93} INFO -   File "/home/***/.local/lib/python3.8/site-packages/aiohttp/connector.py", line 1155, in _create_direct_connection
[2023-09-01T06:58:13.778+0000] {subprocess.py:93} INFO -     hosts = await asyncio.shield(host_resolved)
[2023-09-01T06:58:13.788+0000] {subprocess.py:93} INFO -   File "/home/***/.local/lib/python3.8/site-packages/aiohttp/connector.py", line 874, in _resolve_host
[2023-09-01T06:58:13.794+0000] {subprocess.py:93} INFO -     addrs = await self._resolver.resolve(host, port, family=self._family)
[2023-09-01T06:58:13.796+0000] {subprocess.py:93} INFO -   File "/home/***/.local/lib/python3.8/site-packages/aiohttp/resolver.py", line 33, in resolve
[2023-09-01T06:58:13.810+0000] {subprocess.py:93} INFO -     infos = await self._loop.getaddrinfo(
[2023-09-01T06:58:13.813+0000] {subprocess.py:93} INFO -   File "/usr/local/lib/python3.8/asyncio/base_events.py", line 825, in getaddrinfo
[2023-09-01T06:58:13.818+0000] {subprocess.py:93} INFO -     return await self.run_in_executor(
[2023-09-01T06:58:13.821+0000] {subprocess.py:93} INFO -   File "/usr/local/lib/python3.8/concurrent/futures/thread.py", line 57, in run
[2023-09-01T06:58:13.824+0000] {subprocess.py:93} INFO -     result = self.fn(*self.args, **self.kwargs)
[2023-09-01T06:58:13.826+0000] {subprocess.py:93} INFO -   File "/usr/local/lib/python3.8/socket.py", line 918, in getaddrinfo
[2023-09-01T06:58:13.834+0000] {subprocess.py:93} INFO -     for res in _socket.getaddrinfo(host, port, family, type, proto, flags):
[2023-09-01T06:58:13.840+0000] {subprocess.py:93} INFO - socket.gaierror: [Errno -3] Temporary failure in name resolution
[2023-09-01T06:58:13.842+0000] {subprocess.py:93} INFO - 
[2023-09-01T06:58:13.844+0000] {subprocess.py:93} INFO - The above exception was the direct cause of the following exception:
[2023-09-01T06:58:13.847+0000] {subprocess.py:93} INFO - 
[2023-09-01T06:58:13.854+0000] {subprocess.py:93} INFO - Traceback (most recent call last):
[2023-09-01T06:58:13.865+0000] {subprocess.py:93} INFO -   File "src/crawling.py", line 135, in <module>
[2023-09-01T06:58:13.876+0000] {subprocess.py:93} INFO -     main()
[2023-09-01T06:58:13.884+0000] {subprocess.py:93} INFO -   File "src/crawling.py", line 126, in main
[2023-09-01T06:58:13.904+0000] {subprocess.py:93} INFO -     loop.run_until_complete(run(site, main_category, sub_category, date))
[2023-09-01T06:58:13.908+0000] {subprocess.py:93} INFO -   File "/usr/local/lib/python3.8/asyncio/base_events.py", line 616, in run_until_complete
[2023-09-01T06:58:13.933+0000] {subprocess.py:93} INFO -     return future.result()
[2023-09-01T06:58:13.938+0000] {subprocess.py:93} INFO -   File "src/crawling.py", line 92, in run
[2023-09-01T06:58:13.943+0000] {subprocess.py:93} INFO -     await asyncio.gather(*futures)
[2023-09-01T06:58:13.952+0000] {subprocess.py:93} INFO -   File "src/crawling.py", line 69, in get_news
[2023-09-01T06:58:13.956+0000] {subprocess.py:93} INFO -     async for html in detail_html:
[2023-09-01T06:58:13.959+0000] {subprocess.py:93} INFO -   File "src/crawling.py", line 66, in <genexpr>
[2023-09-01T06:58:13.962+0000] {subprocess.py:93} INFO -     detail_html = (await get_html(url) for url in news_detail_urls)
[2023-09-01T06:58:13.967+0000] {subprocess.py:93} INFO -   File "src/crawling.py", line 32, in get_html
[2023-09-01T06:58:13.970+0000] {subprocess.py:93} INFO -     async with session.get(url, headers={'User-Agent':'Mozilla/5.0'}) as resp:
[2023-09-01T06:58:13.980+0000] {subprocess.py:93} INFO -   File "/home/***/.local/lib/python3.8/site-packages/aiohttp/client.py", line 1141, in __aenter__
[2023-09-01T06:58:13.996+0000] {subprocess.py:93} INFO -     self._resp = await self._coro
[2023-09-01T06:58:14.008+0000] {subprocess.py:93} INFO -   File "/home/***/.local/lib/python3.8/site-packages/aiohttp/client.py", line 536, in _request
[2023-09-01T06:58:14.016+0000] {subprocess.py:93} INFO -     conn = await self._connector.connect(
[2023-09-01T06:58:14.032+0000] {subprocess.py:93} INFO -   File "/home/***/.local/lib/python3.8/site-packages/aiohttp/connector.py", line 540, in connect
[2023-09-01T06:58:14.042+0000] {subprocess.py:93} INFO -     proto = await self._create_connection(req, traces, timeout)
[2023-09-01T06:58:14.052+0000] {subprocess.py:93} INFO -   File "/home/***/.local/lib/python3.8/site-packages/aiohttp/connector.py", line 901, in _create_connection
[2023-09-01T06:58:14.058+0000] {subprocess.py:93} INFO -     _, proto = await self._create_direct_connection(req, traces, timeout)
[2023-09-01T06:58:14.070+0000] {subprocess.py:93} INFO -   File "/home/***/.local/lib/python3.8/site-packages/aiohttp/connector.py", line 1169, in _create_direct_connection
[2023-09-01T06:58:14.080+0000] {subprocess.py:93} INFO -     raise ClientConnectorError(req.connection_key, exc) from exc
[2023-09-01T06:58:14.099+0000] {subprocess.py:93} INFO - aiohttp.client_exceptions.ClientConnectorError: Cannot connect to host hankookilbo.com:443 ssl:default [Temporary failure in name resolution]
[2023-09-01T06:58:15.150+0000] {subprocess.py:97} INFO - Command exited with return code 1
[2023-09-01T06:58:15.210+0000] {taskinstance.py:1943} ERROR - Task failed with exception
Traceback (most recent call last):
  File "/home/airflow/.local/lib/python3.8/site-packages/airflow/operators/bash.py", line 210, in execute
    raise AirflowException(
airflow.exceptions.AirflowException: Bash command failed. The command returned a non-zero exit code 1.
[2023-09-01T06:58:15.276+0000] {taskinstance.py:1400} INFO - Marking task as FAILED. dag_id=bash_test, task_id=international, execution_date=20230831T065200, start_date=20230901T065655, end_date=20230901T065815
[2023-09-01T06:58:15.347+0000] {standard_task_runner.py:104} ERROR - Failed to execute job 73 for task international (Bash command failed. The command returned a non-zero exit code 1.; 25121)
[2023-09-01T06:58:15.432+0000] {local_task_job_runner.py:228} INFO - Task exited with return code 1
[2023-09-01T06:58:15.526+0000] {taskinstance.py:2784} INFO - 0 downstream tasks scheduled from follow-on schedule check
