[2023-09-01T06:37:40.668+0000] {taskinstance.py:1159} INFO - Dependencies all met for dep_context=non-requeueable deps ti=<TaskInstance: bash_test.entertainment manual__2023-09-01T06:37:01.593881+00:00 [queued]>
[2023-09-01T06:37:40.733+0000] {taskinstance.py:1159} INFO - Dependencies all met for dep_context=requeueable deps ti=<TaskInstance: bash_test.entertainment manual__2023-09-01T06:37:01.593881+00:00 [queued]>
[2023-09-01T06:37:40.735+0000] {taskinstance.py:1361} INFO - Starting attempt 1 of 1
[2023-09-01T06:37:40.799+0000] {taskinstance.py:1382} INFO - Executing <Task(BashOperator): entertainment> on 2023-09-01 06:37:01.593881+00:00
[2023-09-01T06:37:40.817+0000] {standard_task_runner.py:57} INFO - Started process 17173 to run task
[2023-09-01T06:37:40.895+0000] {standard_task_runner.py:84} INFO - Running: ['***', 'tasks', 'run', 'bash_test', 'entertainment', 'manual__2023-09-01T06:37:01.593881+00:00', '--job-id', '54', '--raw', '--subdir', 'DAGS_FOLDER/test_dags2.py', '--cfg-path', '/tmp/tmpjz9oobhv']
[2023-09-01T06:37:40.906+0000] {standard_task_runner.py:85} INFO - Job 54: Subtask entertainment
[2023-09-01T06:37:41.204+0000] {task_command.py:415} INFO - Running <TaskInstance: bash_test.entertainment manual__2023-09-01T06:37:01.593881+00:00 [running]> on host 8ef33824b8b6
[2023-09-01T06:37:41.566+0000] {taskinstance.py:1660} INFO - Exporting env vars: AIRFLOW_CTX_DAG_OWNER='***' AIRFLOW_CTX_DAG_ID='bash_test' AIRFLOW_CTX_TASK_ID='entertainment' AIRFLOW_CTX_EXECUTION_DATE='2023-09-01T06:37:01.593881+00:00' AIRFLOW_CTX_TRY_NUMBER='1' AIRFLOW_CTX_DAG_RUN_ID='manual__2023-09-01T06:37:01.593881+00:00'
[2023-09-01T06:37:41.569+0000] {subprocess.py:63} INFO - Tmp dir root location: /tmp
[2023-09-01T06:37:41.581+0000] {subprocess.py:75} INFO - Running command: ['/bin/bash', '-c', 'cd /opt/***/ && python src/crawling.py -s hankook -c entertainment -d 20230831']
[2023-09-01T06:37:41.648+0000] {subprocess.py:86} INFO - Output:
[2023-09-01T06:39:22.655+0000] {subprocess.py:93} INFO - Culture ['HF99', 'HF02', 'HF03', 'HF04', 'HF05', 'HF06'] 20230831
[2023-09-01T06:39:23.011+0000] {subprocess.py:93} INFO - Traceback (most recent call last):
[2023-09-01T06:39:23.053+0000] {subprocess.py:93} INFO -   File "/home/***/.local/lib/python3.8/site-packages/aiohttp/connector.py", line 1155, in _create_direct_connection
[2023-09-01T06:39:23.057+0000] {subprocess.py:93} INFO -     hosts = await asyncio.shield(host_resolved)
[2023-09-01T06:39:23.061+0000] {subprocess.py:93} INFO -   File "/home/***/.local/lib/python3.8/site-packages/aiohttp/connector.py", line 874, in _resolve_host
[2023-09-01T06:39:23.064+0000] {subprocess.py:93} INFO -     addrs = await self._resolver.resolve(host, port, family=self._family)
[2023-09-01T06:39:23.068+0000] {subprocess.py:93} INFO -   File "/home/***/.local/lib/python3.8/site-packages/aiohttp/resolver.py", line 33, in resolve
[2023-09-01T06:39:23.070+0000] {subprocess.py:93} INFO -     infos = await self._loop.getaddrinfo(
[2023-09-01T06:39:23.073+0000] {subprocess.py:93} INFO -   File "/usr/local/lib/python3.8/asyncio/base_events.py", line 825, in getaddrinfo
[2023-09-01T06:39:23.075+0000] {subprocess.py:93} INFO -     return await self.run_in_executor(
[2023-09-01T06:39:23.077+0000] {subprocess.py:93} INFO -   File "/usr/local/lib/python3.8/concurrent/futures/thread.py", line 57, in run
[2023-09-01T06:39:23.090+0000] {subprocess.py:93} INFO -     result = self.fn(*self.args, **self.kwargs)
[2023-09-01T06:39:23.092+0000] {subprocess.py:93} INFO -   File "/usr/local/lib/python3.8/socket.py", line 918, in getaddrinfo
[2023-09-01T06:39:23.095+0000] {subprocess.py:93} INFO -     for res in _socket.getaddrinfo(host, port, family, type, proto, flags):
[2023-09-01T06:39:23.097+0000] {subprocess.py:93} INFO - socket.gaierror: [Errno -3] Temporary failure in name resolution
[2023-09-01T06:39:23.230+0000] {subprocess.py:93} INFO - 
[2023-09-01T06:39:23.272+0000] {subprocess.py:93} INFO - The above exception was the direct cause of the following exception:
[2023-09-01T06:39:23.321+0000] {subprocess.py:93} INFO - 
[2023-09-01T06:39:23.332+0000] {subprocess.py:93} INFO - Traceback (most recent call last):
[2023-09-01T06:39:23.383+0000] {subprocess.py:93} INFO -   File "src/crawling.py", line 135, in <module>
[2023-09-01T06:39:23.428+0000] {subprocess.py:93} INFO -     main()
[2023-09-01T06:39:23.439+0000] {subprocess.py:93} INFO -   File "src/crawling.py", line 126, in main
[2023-09-01T06:39:23.451+0000] {subprocess.py:93} INFO -     loop.run_until_complete(run(site, main_category, sub_category, date))
[2023-09-01T06:39:23.525+0000] {subprocess.py:93} INFO -   File "/usr/local/lib/python3.8/asyncio/base_events.py", line 616, in run_until_complete
[2023-09-01T06:39:23.651+0000] {subprocess.py:93} INFO -     return future.result()
[2023-09-01T06:39:23.682+0000] {subprocess.py:93} INFO -   File "src/crawling.py", line 92, in run
[2023-09-01T06:39:23.704+0000] {subprocess.py:93} INFO -     await asyncio.gather(*futures)
[2023-09-01T06:39:23.714+0000] {subprocess.py:93} INFO -   File "src/crawling.py", line 69, in get_news
[2023-09-01T06:39:23.726+0000] {subprocess.py:93} INFO -     async for html in detail_html:
[2023-09-01T06:39:23.730+0000] {subprocess.py:93} INFO -   File "src/crawling.py", line 66, in <genexpr>
[2023-09-01T06:39:23.741+0000] {subprocess.py:93} INFO -     detail_html = (await get_html(url) for url in news_detail_urls)
[2023-09-01T06:39:23.751+0000] {subprocess.py:93} INFO -   File "src/crawling.py", line 32, in get_html
[2023-09-01T06:39:23.759+0000] {subprocess.py:93} INFO -     async with session.get(url, headers={'User-Agent':'Mozilla/5.0'}) as resp:
[2023-09-01T06:39:23.768+0000] {subprocess.py:93} INFO -   File "/home/***/.local/lib/python3.8/site-packages/aiohttp/client.py", line 1141, in __aenter__
[2023-09-01T06:39:23.780+0000] {subprocess.py:93} INFO -     self._resp = await self._coro
[2023-09-01T06:39:23.797+0000] {subprocess.py:93} INFO -   File "/home/***/.local/lib/python3.8/site-packages/aiohttp/client.py", line 536, in _request
[2023-09-01T06:39:23.802+0000] {subprocess.py:93} INFO -     conn = await self._connector.connect(
[2023-09-01T06:39:23.816+0000] {subprocess.py:93} INFO -   File "/home/***/.local/lib/python3.8/site-packages/aiohttp/connector.py", line 540, in connect
[2023-09-01T06:39:23.828+0000] {subprocess.py:93} INFO -     proto = await self._create_connection(req, traces, timeout)
[2023-09-01T06:39:23.842+0000] {subprocess.py:93} INFO -   File "/home/***/.local/lib/python3.8/site-packages/aiohttp/connector.py", line 901, in _create_connection
[2023-09-01T06:39:23.851+0000] {subprocess.py:93} INFO -     _, proto = await self._create_direct_connection(req, traces, timeout)
[2023-09-01T06:39:23.864+0000] {subprocess.py:93} INFO -   File "/home/***/.local/lib/python3.8/site-packages/aiohttp/connector.py", line 1169, in _create_direct_connection
[2023-09-01T06:39:23.878+0000] {subprocess.py:93} INFO -     raise ClientConnectorError(req.connection_key, exc) from exc
[2023-09-01T06:39:23.882+0000] {subprocess.py:93} INFO - aiohttp.client_exceptions.ClientConnectorError: Cannot connect to host hankookilbo.com:443 ssl:default [Temporary failure in name resolution]
[2023-09-01T06:39:25.232+0000] {subprocess.py:97} INFO - Command exited with return code 1
[2023-09-01T06:39:25.361+0000] {taskinstance.py:1943} ERROR - Task failed with exception
Traceback (most recent call last):
  File "/home/airflow/.local/lib/python3.8/site-packages/airflow/operators/bash.py", line 210, in execute
    raise AirflowException(
airflow.exceptions.AirflowException: Bash command failed. The command returned a non-zero exit code 1.
[2023-09-01T06:39:25.459+0000] {taskinstance.py:1400} INFO - Marking task as FAILED. dag_id=bash_test, task_id=entertainment, execution_date=20230901T063701, start_date=20230901T063740, end_date=20230901T063925
[2023-09-01T06:39:25.659+0000] {standard_task_runner.py:104} ERROR - Failed to execute job 54 for task entertainment (Bash command failed. The command returned a non-zero exit code 1.; 17173)
[2023-09-01T06:39:25.736+0000] {local_task_job_runner.py:228} INFO - Task exited with return code 1
[2023-09-01T06:39:25.906+0000] {taskinstance.py:2784} INFO - 0 downstream tasks scheduled from follow-on schedule check
