[2023-09-02T09:19:04.938+0000] {taskinstance.py:1159} INFO - Dependencies all met for dep_context=non-requeueable deps ti=<TaskInstance: bash_test.society manual__2023-09-02T09:15:43.583597+00:00 [queued]>
[2023-09-02T09:19:04.962+0000] {taskinstance.py:1159} INFO - Dependencies all met for dep_context=requeueable deps ti=<TaskInstance: bash_test.society manual__2023-09-02T09:15:43.583597+00:00 [queued]>
[2023-09-02T09:19:04.965+0000] {taskinstance.py:1361} INFO - Starting attempt 1 of 1
[2023-09-02T09:19:04.998+0000] {taskinstance.py:1382} INFO - Executing <Task(BashOperator): society> on 2023-09-02 09:15:43.583597+00:00
[2023-09-02T09:19:05.012+0000] {standard_task_runner.py:57} INFO - Started process 37038 to run task
[2023-09-02T09:19:05.025+0000] {standard_task_runner.py:84} INFO - Running: ['***', 'tasks', 'run', 'bash_test', 'society', 'manual__2023-09-02T09:15:43.583597+00:00', '--job-id', '98', '--raw', '--subdir', 'DAGS_FOLDER/test_dags2.py', '--cfg-path', '/tmp/tmpvliinjoa']
[2023-09-02T09:19:05.031+0000] {standard_task_runner.py:85} INFO - Job 98: Subtask society
[2023-09-02T09:19:05.166+0000] {task_command.py:415} INFO - Running <TaskInstance: bash_test.society manual__2023-09-02T09:15:43.583597+00:00 [running]> on host 8ef33824b8b6
[2023-09-02T09:19:05.408+0000] {taskinstance.py:1660} INFO - Exporting env vars: AIRFLOW_CTX_DAG_OWNER='***' AIRFLOW_CTX_DAG_ID='bash_test' AIRFLOW_CTX_TASK_ID='society' AIRFLOW_CTX_EXECUTION_DATE='2023-09-02T09:15:43.583597+00:00' AIRFLOW_CTX_TRY_NUMBER='1' AIRFLOW_CTX_DAG_RUN_ID='manual__2023-09-02T09:15:43.583597+00:00'
[2023-09-02T09:19:05.423+0000] {subprocess.py:63} INFO - Tmp dir root location: /tmp
[2023-09-02T09:19:05.426+0000] {subprocess.py:75} INFO - Running command: ['/bin/bash', '-c', 'cd /opt/***/ && python src/crawling.py -s hankook -c society -d 20230901']
[2023-09-02T09:19:05.454+0000] {subprocess.py:86} INFO - Output:
[2023-09-02T09:20:19.291+0000] {subprocess.py:93} INFO - Society ['HC01', 'HC02', 'HC03', 'HC04', 'HC05', 'HC06', 'HC99'] 20230901
[2023-09-02T09:20:19.412+0000] {subprocess.py:93} INFO - Traceback (most recent call last):
[2023-09-02T09:20:19.417+0000] {subprocess.py:93} INFO -   File "/home/***/.local/lib/python3.8/site-packages/aiohttp/connector.py", line 1155, in _create_direct_connection
[2023-09-02T09:20:19.425+0000] {subprocess.py:93} INFO -     hosts = await asyncio.shield(host_resolved)
[2023-09-02T09:20:19.432+0000] {subprocess.py:93} INFO -   File "/home/***/.local/lib/python3.8/site-packages/aiohttp/connector.py", line 874, in _resolve_host
[2023-09-02T09:20:19.435+0000] {subprocess.py:93} INFO -     addrs = await self._resolver.resolve(host, port, family=self._family)
[2023-09-02T09:20:19.437+0000] {subprocess.py:93} INFO -   File "/home/***/.local/lib/python3.8/site-packages/aiohttp/resolver.py", line 33, in resolve
[2023-09-02T09:20:19.445+0000] {subprocess.py:93} INFO -     infos = await self._loop.getaddrinfo(
[2023-09-02T09:20:19.449+0000] {subprocess.py:93} INFO -   File "/usr/local/lib/python3.8/asyncio/base_events.py", line 825, in getaddrinfo
[2023-09-02T09:20:19.456+0000] {subprocess.py:93} INFO -     return await self.run_in_executor(
[2023-09-02T09:20:19.459+0000] {subprocess.py:93} INFO -   File "/usr/local/lib/python3.8/concurrent/futures/thread.py", line 57, in run
[2023-09-02T09:20:19.466+0000] {subprocess.py:93} INFO -     result = self.fn(*self.args, **self.kwargs)
[2023-09-02T09:20:19.489+0000] {subprocess.py:93} INFO -   File "/usr/local/lib/python3.8/socket.py", line 918, in getaddrinfo
[2023-09-02T09:20:19.504+0000] {subprocess.py:93} INFO -     for res in _socket.getaddrinfo(host, port, family, type, proto, flags):
[2023-09-02T09:20:19.508+0000] {subprocess.py:93} INFO - socket.gaierror: [Errno -3] Temporary failure in name resolution
[2023-09-02T09:20:19.514+0000] {subprocess.py:93} INFO - 
[2023-09-02T09:20:19.522+0000] {subprocess.py:93} INFO - The above exception was the direct cause of the following exception:
[2023-09-02T09:20:19.525+0000] {subprocess.py:93} INFO - 
[2023-09-02T09:20:19.532+0000] {subprocess.py:93} INFO - Traceback (most recent call last):
[2023-09-02T09:20:19.538+0000] {subprocess.py:93} INFO -   File "src/crawling.py", line 135, in <module>
[2023-09-02T09:20:19.548+0000] {subprocess.py:93} INFO -     main()
[2023-09-02T09:20:19.551+0000] {subprocess.py:93} INFO -   File "src/crawling.py", line 126, in main
[2023-09-02T09:20:19.553+0000] {subprocess.py:93} INFO -     loop.run_until_complete(run(site, main_category, sub_category, date))
[2023-09-02T09:20:19.556+0000] {subprocess.py:93} INFO -   File "/usr/local/lib/python3.8/asyncio/base_events.py", line 616, in run_until_complete
[2023-09-02T09:20:19.558+0000] {subprocess.py:93} INFO -     return future.result()
[2023-09-02T09:20:19.568+0000] {subprocess.py:93} INFO -   File "src/crawling.py", line 92, in run
[2023-09-02T09:20:19.570+0000] {subprocess.py:93} INFO -     await asyncio.gather(*futures)
[2023-09-02T09:20:19.573+0000] {subprocess.py:93} INFO -   File "src/crawling.py", line 69, in get_news
[2023-09-02T09:20:19.576+0000] {subprocess.py:93} INFO -     async for html in detail_html:
[2023-09-02T09:20:19.580+0000] {subprocess.py:93} INFO -   File "src/crawling.py", line 66, in <genexpr>
[2023-09-02T09:20:19.583+0000] {subprocess.py:93} INFO -     detail_html = (await get_html(url) for url in news_detail_urls)
[2023-09-02T09:20:19.587+0000] {subprocess.py:93} INFO -   File "src/crawling.py", line 32, in get_html
[2023-09-02T09:20:19.591+0000] {subprocess.py:93} INFO -     async with session.get(url, headers={'User-Agent':'Mozilla/5.0'}) as resp:
[2023-09-02T09:20:19.599+0000] {subprocess.py:93} INFO -   File "/home/***/.local/lib/python3.8/site-packages/aiohttp/client.py", line 1141, in __aenter__
[2023-09-02T09:20:19.602+0000] {subprocess.py:93} INFO -     self._resp = await self._coro
[2023-09-02T09:20:19.605+0000] {subprocess.py:93} INFO -   File "/home/***/.local/lib/python3.8/site-packages/aiohttp/client.py", line 536, in _request
[2023-09-02T09:20:19.610+0000] {subprocess.py:93} INFO -     conn = await self._connector.connect(
[2023-09-02T09:20:19.615+0000] {subprocess.py:93} INFO -   File "/home/***/.local/lib/python3.8/site-packages/aiohttp/connector.py", line 540, in connect
[2023-09-02T09:20:19.621+0000] {subprocess.py:93} INFO -     proto = await self._create_connection(req, traces, timeout)
[2023-09-02T09:20:19.625+0000] {subprocess.py:93} INFO -   File "/home/***/.local/lib/python3.8/site-packages/aiohttp/connector.py", line 901, in _create_connection
[2023-09-02T09:20:19.627+0000] {subprocess.py:93} INFO -     _, proto = await self._create_direct_connection(req, traces, timeout)
[2023-09-02T09:20:19.629+0000] {subprocess.py:93} INFO -   File "/home/***/.local/lib/python3.8/site-packages/aiohttp/connector.py", line 1169, in _create_direct_connection
[2023-09-02T09:20:19.635+0000] {subprocess.py:93} INFO -     raise ClientConnectorError(req.connection_key, exc) from exc
[2023-09-02T09:20:19.637+0000] {subprocess.py:93} INFO - aiohttp.client_exceptions.ClientConnectorError: Cannot connect to host www.hankookilbo.com:443 ssl:default [Temporary failure in name resolution]
[2023-09-02T09:20:20.107+0000] {subprocess.py:97} INFO - Command exited with return code 1
[2023-09-02T09:20:20.150+0000] {taskinstance.py:1943} ERROR - Task failed with exception
Traceback (most recent call last):
  File "/home/airflow/.local/lib/python3.8/site-packages/airflow/operators/bash.py", line 210, in execute
    raise AirflowException(
airflow.exceptions.AirflowException: Bash command failed. The command returned a non-zero exit code 1.
[2023-09-02T09:20:20.165+0000] {taskinstance.py:1400} INFO - Marking task as FAILED. dag_id=bash_test, task_id=society, execution_date=20230902T091543, start_date=20230902T091904, end_date=20230902T092020
[2023-09-02T09:20:20.201+0000] {standard_task_runner.py:104} ERROR - Failed to execute job 98 for task society (Bash command failed. The command returned a non-zero exit code 1.; 37038)
[2023-09-02T09:20:20.251+0000] {local_task_job_runner.py:228} INFO - Task exited with return code 1
[2023-09-02T09:20:20.318+0000] {taskinstance.py:2784} INFO - 0 downstream tasks scheduled from follow-on schedule check
